Workbook

Sheet Dashboard
A1: Skin Care Supply Chain Financial Model - Dashboard
A3: Key Financial Metrics
A4: Metric | B4: Year 1 | C4: Year 2 | D4: Year 3 | E4: Year 4 | F4: Year 5
A5: Total Revenue | B5: =Revenue!F13 | C5: =Revenue!G13 | D5: =Revenue!H13 | E5: =Revenue!I13 | F5: =Revenue!J13
A6: Gross Profit | B6: =Revenue!F19 | C6: =Revenue!G19 | D6: =Revenue!H19 | E6: =Revenue!I19 | F6: =Revenue!J19
A7: Gross Margin % | B7: =Revenue!F20 | C7: =Revenue!G20 | D7: =Revenue!H20 | E7: =Revenue!I20 | F7: =Revenue!J20
A8: EBITDA | B8: =Revenue!F23 | C8: =Revenue!G23 | D8: =Revenue!H23 | E8: =Revenue!I23 | F8: =Revenue!J23
A9: EBITDA Margin % | B9: =Revenue!F24 | C9: =Revenue!G24 | D9: =Revenue!H24 | E9: =Revenue!I24 | F9: =Revenue!J24
A10: Net Income | B10: =Revenue!F31 | C10: =Revenue!G31 | D10: =Revenue!H31 | E10: =Revenue!I31 | F10: =Revenue!J31
A11: Net Profit Margin % | B11: =Revenue!F32 | C11: =Revenue!G32 | D11: =Revenue!H32 | E11: =Revenue!I32 | F11: =Revenue!J32
A12: COGS as % of Revenue | B12: =COGS!F30/Revenue!F13 | C12: =COGS!G30/Revenue!G13 | D12: =COGS!H30/Revenue!H13 | E12: =COGS!I30/Revenue!I13 | F12: =COGS!J30/Revenue!J13
A13: SG&A as % of Revenue | B13: ='SG&A'!F40/Revenue!F13 | C13: ='SG&A'!G40/Revenue!G13 | D13: ='SG&A'!H40/Revenue!H13 | E13: ='SG&A'!I40/Revenue!I13 | F13: ='SG&A'!J40/Revenue!J13
A14: Operational Costs as % of Revenue | B14: ='Operational Costs'!F30/Revenue!F13 | C14: ='Operational Costs'!G30/Revenue!G13 | D14: ='Operational Costs'!H30/Revenue!H13 | E14: ='Operational Costs'!I30/Revenue!I13 | F14: ='Operational Costs'!J30/Revenue!J13
A15: Cost Structure
A16: Cost Category | B16: Year 1 Amount | C16: % of Total Costs
A17: Raw Materials | B17: =100000 | C17: =B17/SUM(B17:B28)
A18: Packaging Materials | B18: =100000 | C18: =B18/SUM(B17:B28)
A19: Direct Labor | B19: =100000 | C19: =B19/SUM(B17:B28)
A20: Manufacturing Overhead | B20: =100000 | C20: =B20/SUM(B17:B28)
A21: Contract Manufacturing | B21: =100000 | C21: =B21/SUM(B17:B28)
A22: Quality Control | B22: =100000 | C22: =B22/SUM(B17:B28)
A23: Freight & Logistics (Inbound) | B23: =100000 | C23: =B23/SUM(B17:B28)
A24: Facility Costs | B24: =150000 | C24: =B24/SUM(B17:B28)
A25: Equipment Costs | B25: =150000 | C25: =B25/SUM(B17:B28)
A26: Supply Chain Costs | B26: =150000 | C26: =B26/SUM(B17:B28)
A27: Sales Expenses | B27: =200000 | C27: =B27/SUM(B17:B28)
A28: Marketing Expenses | B28: =200000 | C28: =B28/SUM(B17:B28)
A29: Revenue Breakdown
A30: Revenue Category | B30: Year 1 Amount | C30: % of Total Revenue
A31: Facial Skincare | B31: =Revenue!F3 | C31: =B31/Revenue!F13
A32: Body Care | B32: =Revenue!F4 | C32: =B32/Revenue!F13
A33: Specialty Products | B33: =Revenue!F5 | C33: =B33/Revenue!F13
A34: Direct-to-Consumer (DTC) | B34: =Revenue!F6 | C34: =B34/Revenue!F13
A35: Retail | B35: =Revenue!F7 | C35: =B35/Revenue!F13
A36: Wholesale/B2B | B36: =Revenue!F8 | C36: =B36/Revenue!F13
A37: Domestic | B37: =Revenue!F9 | C37: =B37/Revenue!F13
A38: International - Developed | B38: =Revenue!F10 | C38: =B38/Revenue!F13
A39: International - Emerging | B39: =Revenue!F11 | C39: =B39/Revenue!F13

Sheet Group Model
A1: Skin Care Supply Chain Group Financial Model
A3: Group Financial Summary
A4: Entity/Metric | B4: Year 1 | C4: Year 2 | D4: Year 3 | E4: Year 4 | F4: Year 5
A5: Manufacturing Entity
A6: Revenue | B6: =Revenue!F13*0.4 | C6: =Revenue!G13*0.4 | D6: =Revenue!H13*0.4 | E6: =Revenue!I13*0.4 | F6: =Revenue!J13*0.4
A7: Cost of Goods Sold (COGS) | B7: =B7*0.8 | C7: =C7*0.8 | D7: =D7*0.8 | E7: =E7*0.8 | F7: =F7*0.8
A8: Gross Profit | B8: =B6-B7 | C8: =C6-C7 | D8: =D6-D7 | E8: =E6-E7 | F8: =F6-F7
A9: Gross Margin % | B9: =B8/B6 | C9: =C8/C6 | D9: =D8/D6 | E9: =E8/E6 | F9: =F8/F6
A10: Operational Costs | B10: =B6*0.1 | C10: =C6*0.1 | D10: =D6*0.1 | E10: =E6*0.1 | F10: =F6*0.1
A11: SG&A Expenses | B11: =B6*0.05 | C11: =C6*0.05 | D11: =D6*0.05 | E11: =E6*0.05 | F11: =F6*0.05
A12: EBITDA | B12: =B8-B10-B11 | C12: =C8-C10-C11 | D12: =D8-D10-D11 | E12: =E8-E10-E11 | F12: =F8-F10-F11
A13: EBITDA Margin % | B13: =B12/B6 | C13: =C12/C6 | D13: =D12/D6 | E13: =E12/E6 | F13: =F12/F6
A14: Depreciation & Amortization | B14: =50000 | C14: =50000 | D14: =50000 | E14: =50000 | F14: =50000
A15: EBIT | B15: =B12-B14 | C15: =C12-C14 | D15: =D12-D14 | E15: =E12-E14 | F15: =F12-F14
A16: Interest Expense | B16: =20000 | C16: =20000 | D16: =20000 | E16: =20000 | F16: =20000
A17: EBT | B17: =B15-B16 | C17: =C15-C16 | D17: =D15-D16 | E17: =E15-E16 | F17: =F15-F16
A18: Income Tax | B18: =B17*0.25 | C18: =C17*0.25 | D18: =D17*0.25 | E18: =E17*0.25 | F18: =F17*0.25
A19: Net Income | B19: =B17-B18 | C19: =C17-C18 | D19: =D17-D18 | E19: =E17-E18 | F19: =F17-F18
A20: Net Profit Margin % | B20: =B19/B6 | C20: =C19/C6 | D20: =D19/D6 | E20: =E19/E6 | F20: =F19/F6
A22: Distribution Entity
A23: Revenue | B23: =Revenue!F13*0.3 | C23: =Revenue!G13*0.3 | D23: =Revenue!H13*0.3 | E23: =Revenue!I13*0.3 | F23: =Revenue!J13*0.3
A24: Cost of Goods Sold (COGS) | B24: =B24*0.7 | C24: =C24*0.7 | D24: =D24*0.7 | E24: =E24*0.7 | F24: =F24*0.7
A25: Gross Profit | B25: =B23-B24 | C25: =C23-C24 | D25: =D23-D24 | E25: =E23-E24 | F25: =F23-F24
A26: Gross Margin % | B26: =B25/B23 | C26: =C25/C23 | D26: =D25/D23 | E26: =E25/E23 | F26: =F25/F23
A27: Operational Costs | B27: =B23*0.15 | C27: =C23*0.15 | D27: =D23*0.15 | E27: =E23*0.15 | F27: =F23*0.15
A28: SG&A Expenses | B28: =B23*0.08 | C28: =C23*0.08 | D28: =D23*0.08 | E28: =E23*0.08 | F28: =F23*0.08
A29: EBITDA | B29: =B25-B27-B28 | C29: =C25-C27-C28 | D29: =D25-D27-D28 | E29: =E25-E27-E28 | F29: =F25-F27-F28
A30: EBITDA Margin % | B30: =B29/B23 | C30: =C29/C23 | D30: =D29/D23 | E30: =E29/E23 | F30: =F29/F23
A31: Depreciation & Amortization | B31: =30000 | C31: =30000 | D31: =30000 | E31: =30000 | F31: =30000
A32: EBIT | B32: =B29-B31 | C32: =C29-C31 | D32: =D29-D31 | E32: =E29-E31 | F32: =F29-F31
A33: Interest Expense | B33: =15000 | C33: =15000 | D33: =15000 | E33: =15000 | F33: =15000
A34: EBT | B34: =B32-B33 | C34: =C32-C33 | D34: =D32-D33 | E34: =E32-E33 | F34: =F32-F33
A35: Income Tax | B35: =B34*0.25 | C35: =C34*0.25 | D35: =D34*0.25 | E35: =E34*0.25 | F35: =F34*0.25
A36: Net Income | B36: =B34-B35 | C36: =C34-C35 | D36: =D34-D35 | E36: =E34-E35 | F36: =F34-F35
A37: Net Profit Margin % | B37: =B36/B23 | C37: =C36/C23 | D37: =D36/D23 | E37: =E36/E23 | F37: =F36/F23
A39: Retail Entity
A40: Revenue | B40: =Revenue!F13*0.5 | C40: =Revenue!G13*0.5 | D40: =Revenue!H13*0.5 | E40: =Revenue!I13*0.5 | F40: =Revenue!J13*0.5
A41: Cost of Goods Sold (COGS) | B41: =B41*0.6 | C41: =C41*0.6 | D41: =D41*0.6 | E41: =E41*0.6 | F41: =F41*0.6
A42: Gross Profit | B42: =B40-B41 | C42: =C40-C41 | D42: =D40-D41 | E42: =E40-E41 | F42: =F40-F41
A43: Gross Margin % | B43: =B42/B40 | C43: =C42/C40 | D43: =D42/D40 | E43: =E42/E40 | F43: =F42/F40
...

Sheet Assumptions
A1: Financial Model Assumptions
A2: Category | B2: Assumption | C2: Year 1 | D2: Year 2 | E2: Year 3 | F2: Year 4 | G2: Year 5 | H2: Notes/Drivers
A3: Global Assumptions | B3: Projection Start Year | C3: 2025 | D3: 2026 | E3: 2027 | F3: 2028 | G3: 2029 | H3: Starting year for the financial projections.
A4: Global Assumptions | B4: Projection Period (Years) | C4: 5 | D4: 5 | E4: 5 | F4: 5 | G4: 5 | H4: Duration of the forecast.
A5: Global Assumptions | B5: Currency | C5: USD | D5: USD | E5: USD | F5: USD | G5: USD | H5: Reporting currency (e.g., USD, EUR).
A6: Global Assumptions | B6: Inflation Rate (%) | C6: 2.5% | D6: 2.3% | E6: 2.2% | F6: 2.1% | G6: 2.0% | H6: Assumed general inflation rate.
A7: Global Assumptions | B7: Interest Rate (Base, %) | C7: 4.0% | D7: 4.0% | E7: 4.0% | F7: 4.0% | G7: 4.0% | H7: Base interest rate for debt calculations.
A8: Global Assumptions | B8: Corporate Tax Rate (%) | C8: 25.0% | D8: 25.0% | E8: 25.0% | F8: 25.0% | G8: 25.0% | H8: Effective corporate income tax rate.
A9: Revenue Assumptions | B9: Overall Market Growth Rate (%) | C9: 5.0% | D9: 5.2% | E9: 5.4% | F9: 5.6% | G9: 5.8% | H9: Assumed annual growth rate for the overall skin care market.
A10: Revenue Assumptions | B10: Product Category 1 Growth Rate (%) | C10: 6.0% | D10: 6.5% | E10: 7.0% | F10: 7.5% | G10: 8.0% | H10: Specific growth rate for Product Category 1.
A11: Revenue Assumptions | B11: Product Category 2 Growth Rate (%) | C11: 4.0% | D11: 4.2% | E11: 4.5% | F11: 4.8% | G11: 5.0% | H11: Specific growth rate for Product Category 2.
A12: Revenue Assumptions | B12: Channel 1 (DTC) Growth Rate (%) | C12: 8.0% | D12: 9.0% | E12: 10.0% | F12: 11.0% | G12: 12.0% | H12: Growth rate for Direct-to-Consumer channel.
A13: Revenue Assumptions | B13: Channel 2 (Retail) Growth Rate (%) | C13: 3.0% | D13: 3.2% | E13: 3.5% | F13: 3.8% | G13: 4.0% | H13: Growth rate for Retail channel.
... A78: Sustainability & Compliance Assumptions | B78: Supply Chain Audit Costs (Annual) | C78: $25,000 | D78: $25,500 | E78: $26,000 | F78: $26,500 | G78: $27,000 | H78: Annual cost for auditing supply chain partners.

Sheet Operational Costs
A1: Operational Costs
A2: Cost Category | B2: Cost Item | C2: Cost Driver | D2: Monthly Cost Base | E2: Units | F2: Year 1 Total | G2: Year 2 Total | H2: Year 3 Total | I2: Year 4 Total | J2: Year 5 Total | K2: Notes
A3: Facility Costs | B3: Rent/Lease | C3: Square footage × rate with annual increase | D3: =Assumptions!C19/12 | E3: 12 | F3: =D3*E3 | G3: =F3*(1+Assumptions!D19) | H3: =G3*(1+Assumptions!E19) | I3: =H3*(1+Assumptions!F19) | J3: =I3*(1+Assumptions!G19) | K3: Monthly rent/lease payments for manufacturing and warehouse facilities
A4: Facility Costs | B4: Utilities | C4: Usage rates × utility prices with annual increase | D4: =Assumptions!C20/12 | E4: 12 | F4: =D4*E4 | G4: =F4*(1+Assumptions!D20) | H4: =G4*(1+Assumptions!E20) | I4: =H4*(1+Assumptions!F20) | J4: =I4*(1+Assumptions!G20) | K4: Electricity, water, gas, and other utility costs
A5: Facility Costs | B5: Maintenance & Repairs | C5: Percentage of facility value | D5: =Assumptions!C21/12 | E5: 12 | F5: =D5*E5 | G5: =F5*(1+Assumptions!D4) | H5: =G5*(1+Assumptions!E4) | I5: =H5*(1+Assumptions!F4) | J5: =I5*(1+Assumptions!G4) | K5: Ongoing maintenance and repairs for facilities
A6: Facility Costs | B6: Property Insurance | C6: Insurance premium based on asset value | D6: =Assumptions!C22/12 | E6: 12 | F6: =D6*E6 | G6: =F6*(1+Assumptions!D4) | H6: =G6*(1+Assumptions!E4) | I6: =H6*(1+Assumptions!F4) | J6: =I6*(1+Assumptions!G4) | K6: Insurance coverage for facilities and contents
A7: Facility Costs | B7: Property Taxes | C7: Local tax rates on property value | D7: =Assumptions!C23/12 | E7: 12 | F7: =D7*E7 | G7: =F7*(1+Assumptions!D4) | H7: =G7*(1+Assumptions!E4) | I7: =H7*(1+Assumptions!F4) | J7: =I7*(1+Assumptions!G4) | K7: Local property taxes on owned facilities
A8: Equipment Costs | B8: Equipment Maintenance | C8: Percentage of equipment value | D8: =Assumptions!C21/12 | E8: 12 | F8: =D8*E8 | G8: =F8*(1+Assumptions!D21) | H8: =G8*(1+Assumptions!E21) | I8: =H8*(1+Assumptions!F21) | J8: =I8*(1+Assumptions!G21) | K8: Regular maintenance of production and packaging equipment
A9: Equipment Costs | B9: Equipment Calibration | C9: Fixed cost per calibration × frequency | D9: =2000 | E9: 4 | F9: =D9*E9 | G9: =F9*(1+Assumptions!D21) | H9: =G9*(1+Assumptions!E21) | I9: =H9*(1+Assumptions!F21) | J9: =I9*(1+Assumptions!G21) | K9: Required calibration of precision equipment
A10: Equipment Costs | B10: Small Equipment Purchases | C10: Replacement cycle for minor equipment | D10: =3000 | E10: 2 | F10: =D10*E10 | G10: =F10*(1+Assumptions!D21) | H10: =G10*(1+Assumptions!E21) | I10: =H10*(1+Assumptions!F21) | J10: =I10*(1+Assumptions!G21) | K10: Replacement of small equipment items not capitalized
A11: Supply Chain Costs | B11: Supply Chain Software | C11: Fixed annual cost with increases | D11: =Assumptions!C24/12 | E11: 12 | F11: =D11*E11 | G11: =F11*(1+Assumptions!D24) | H11: =G11*(1+Assumptions!E24) | I11: =H11*(1+Assumptions!F24) | J11: =I11*(1+Assumptions!G24) | K11: Software licenses for supply chain management systems
A12: Supply Chain Costs | B12: Inventory Management | C12: Percentage of inventory value | D12: =Assumptions!C22/12 | E12: 12 | F12: =D12*E12 | G12: =F12*(1+Assumptions!D4) | H12: =G12*(1+Assumptions!E4) | I12: =H12*(1+Assumptions!F4) | J12: =I12*(1+Assumptions!G4) | K12: Costs associated with managing inventory levels
A13: Supply Chain Costs | B13: Warehouse Operations | C13: Per square foot cost × warehouse size | D13: =5000 | E13: 12 | F13: =D13*E13 | G13: =F13*(1+Assumptions!D4) | H13: =G13*(1+Assumptions!E4) | I13: =H13*(1+Assumptions!F4) | J13: =I13*(1+Assumptions!G4) | K13: Labor and equipment for warehouse operations
A14: Supply Chain Costs | B14: Supply Chain Consulting | C14: Project-based consulting fees | D14: =2500 | E14: 4 | F14: =D14*E14 | G14: =F14*(1+Assumptions!D4) | H14: =G14*(1+Assumptions!E4) | I14: =H14*(1+Assumptions!F4) | J14: =I14*(1+Assumptions!G4) | K14: External supply chain optimization consultants
A15: Quality Control Costs | B15: Quality Testing | C15: Cost per test × number of batches | D15: =4000 | E15: 24 | F15: =D15*E15 | G15: =F15*(1+Assumptions!D4) | H15: =G15*(1+Assumptions!E4) | I15: =H15*(1+Assumptions!F4) | J15: =I15*(1+Assumptions!G4) | K15: Laboratory testing of raw materials and finished products
A16: Quality Control Costs | B16: Quality Certifications | C16: Annual certification fees | D16: =1500 | E16: 2 | F16: =D16*E16 | G16: =F16*(1+Assumptions!D4) | H16: =G16*(1+Assumptions!E4) | I16: =H16*(1+Assumptions!F4) | J16: =I16*(1+Assumptions!G4) | K16: Industry and regulatory certifications
A17: Quality Control Costs | B17: Quality Staff | C17: Headcount × average salary | D17: =8000 | E17: 5 | F17: =D17*E17 | G17: =F17*(1+Assumptions!D4) | H17: =G17*(1+Assumptions!E4) | I17: =H17*(1+Assumptions!F4) | J17: =I17*(1+Assumptions!G4) | K17: Quality assurance and control personnel
A18: Sustainability Costs | B18: Sustainability Program | C18: Fixed annual budget with increases | D18: =Assumptions!C25/12 | E18: 12 | F18: =D18*E18 | G18: =F18*(1+Assumptions!D25) | H18: =G18*(1+Assumptions!E25) | I18: =H18*(1+Assumptions!F25) | J18: =I18*(1+Assumptions!G25) | K18: Corporate sustainability initiatives and programs
A19: Sustainability Costs | B19: Waste Management | C19: Volume of waste × disposal cost | D19: =3000 | E19: 12 | F19: =D19*E19 | G19: =F19*(1+Assumptions!D4) | H19: =G19*(1+Assumptions!E4) | I19: =H19*(1+Assumptions!F4) | J19: =I19*(1+Assumptions!G4) | K19: Disposal and recycling of production waste
A20: Sustainability Costs | B20: Energy Efficiency Initiatives | C20: Project-based initiatives | D20: =2000 | E20: 4 | F20: =D20*E20 | G20: =F20*(1+Assumptions!D4) | H20: =G20*(1+Assumptions!E4) | I20: =H20*(1+Assumptions!F4) | J20: =I20*(1+Assumptions!G4) | K20: Projects to improve energy efficiency
A21: Operational Staff Costs | B21: Production Management | C21: Headcount × average salary | D21: =12000 | E21: 8 | F21: =D21*E21 | G21: =F21*(1+Assumptions!D4) | H21: =G21*(1+Assumptions!E4) | I21: =H21*(1+Assumptions!F4) | J21: =I21*(1+Assumptions!G4) | K21: Production managers and supervisors
A22: Operational Staff Costs | B22: Warehouse Staff | C22: Headcount × average salary | D22: =8000 | E22: 15 | F22: =D22*E22 | G22: =F22*(1+Assumptions!D4) | H22: =G22*(1+Assumptions!E4) | I22: =H22*(1+Assumptions!F4) | J22: =I22*(1+Assumptions!G4) | K22: Warehouse and logistics personnel
A23: Operational Staff Costs | B23: Operations Support | C23: Headcount × average salary | D23: =6000 | E23: 6 | F23: =D23*E23 | G23: =F23*(1+Assumptions!D4) | H23: =G23*(1+Assumptions!E4) | I23: =H23*(1+Assumptions!F4) | J23: =I23*(1+Assumptions!G4) | K23: Operations administrative support staff
A24: Operational Staff Costs | B24: Staff Training | C24: Training budget per employee | D24: =Assumptions!C47/12 | E24: 29 | F24: =D24*E24 | G24: =F24*(1+Assumptions!D4) | H24: =G24*(1+Assumptions!E4) | I24: =H24*(1+Assumptions!F4) | J24: =I24*(1+Assumptions!G4) | K24: Ongoing training for operational staff
A25: Operational Overhead | B25: IT Systems (Operations) | C25: Per user license fees × users | D25: =2500 | E25: 20 | F25: =D25*E25 | G25: =F25*(1+Assumptions!D4) | H25: =G25*(1+Assumptions!E4) | I25: =H25*(1+Assumptions!F4) | J25: =I25*(1+Assumptions!G4) | K25: Software and hardware for operations
A26: Operational Overhead | B26: Communications | C26: Fixed monthly costs | D26: =1000 | E26: 12 | F26: =D26*E26 | G26: =F26*(1+Assumptions!D4) | H26: =G26*(1+Assumptions!E4) | I26: =H26*(1+Assumptions!F4) | J26: =I26*(1+Assumptions!G4) | K26: Phone, internet, and other communication costs
A27: Operational Overhead | B27: Miscellaneous Operational Expenses | C27: Percentage of total operational costs | D27: =0.02*SUM(D4:D26) | E27: 1 | F27: =D27*E27 | G27: =F27*(1+Assumptions!D4) | H27: =G27*(1+Assumptions!E4) | I27: =H27*(1+Assumptions!F4) | J27: =I27*(1+Assumptions!G4) | K27: Miscellaneous expenses related to operations
A29: Total Operational Costs | F29: =SUM(F3:F28) | G29: =SUM(G3:G28) | H29: =SUM(H3:H28) | I29: =SUM(I3:I28) | J29: =SUM(J3:J28)
A31: Operational Costs as % of Revenue | F31: =F29/100000 | G31: =G29/100000 | H31: =H29/100000 | I31: =I29/100000 | J31: =J29/100000

Sheet COGS
A1: Cost of Goods Sold (COGS) and Direct Costs
A2: Cost Category | B2: Cost Item | C2: Cost Driver | D2: Unit Cost | E2: Annual Volume | F2: Year 1 Total | G2: Year 2 Total | H2: Year 3 Total | I2: Year 4 Total | J2: Year 5 Total | K2: Notes
A3: Raw Materials | B3: Active Ingredients | C3: Cost per unit × units produced | D3: 2.50 | E3: =Assumptions!C15*100000 | F3: =D3*E3 | G3: =F3*(1+Assumptions!D14) | H3: =G3*(1+Assumptions!E14) | I3: =H3*(1+Assumptions!F14) | J3: =I3*(1+Assumptions!G14) | K3: Key functional ingredients with specific skin benefits
A4: Raw Materials | B4: Base Ingredients | C4: Cost per unit × units produced | D4: 0.75 | E4: =Assumptions!C15*100000 | F4: =D4*E4 | G4: =F4*(1+Assumptions!D14) | H4: =G4*(1+Assumptions!E14) | I4: =H4*(1+Assumptions!F14) | J4: =I4*(1+Assumptions!G14) | K4: Foundation ingredients that form the product base
A5: Raw Materials | B5: Fragrances | C5: Cost per unit × units produced | D5: 0.50 | E5: =Assumptions!C15*100000 | F5: =D5*E5 | G5: =F5*(1+Assumptions!D14) | H5: =G5*(1+Assumptions!E14) | I5: =H5*(1+Assumptions!F14) | J5: =I5*(1+Assumptions!G14) | K5: Scents and aromatic compounds
A6: Raw Materials | B6: Preservatives | C6: Cost per unit × units produced | D6: 0.25 | E6: =Assumptions!C15*100000 | F6: =D6*E6 | G6: =F6*(1+Assumptions!D14) | H6: =G6*(1+Assumptions!E14) | I6: =H6*(1+Assumptions!F14) | J6: =I6*(1+Assumptions!G14) | K6: Ingredients that extend shelf life
A7: Raw Materials | B7: Other Additives | C7: Cost per unit × units produced | D7: 0.35 | E7: =Assumptions!C15*100000 | F7: =D7*E7 | G7: =F7*(1+Assumptions!D14) | H7: =G7*(1+Assumptions!E14) | I7: =H7*(1+Assumptions!F14) | J7: =I7*(1+Assumptions!G14) | K7: Colorants, thickeners, and other specialty ingredients
A8: Packaging Materials | B8: Primary Packaging | C8: Cost per unit × units produced | D8: 1.20 | E8: =Assumptions!C15*100000 | F8: =D8*E8 | G8: =F8*(1+Assumptions!D14) | H8: =G8*(1+Assumptions!E14) | I8: =H8*(1+Assumptions!F14) | J8: =I8*(1+Assumptions!G14) | K8: Bottles, jars, tubes, pumps that directly contain product
A9: Packaging Materials | B9: Secondary Packaging | C9: Cost per unit × units produced | D9: 0.60 | E9: =Assumptions!C15*100000 | F9: =D9*E9 | G9: =F9*(1+Assumptions!D14) | H9: =G9*(1+Assumptions!E14) | I9: =H9*(1+Assumptions!F14) | J9: =I9*(1+Assumptions!G14) | K9: Boxes, cartons, and outer packaging
A10: Packaging Materials | B10: Labels & Printing | C10: Cost per unit × units produced | D10: 0.25 | E10: =Assumptions!C15*100000 | F10: =D10*E10 | G10: =F10*(1+Assumptions!D14) | H10: =G10*(1+Assumptions!E14) | I10: =H10*(1+Assumptions!F14) | J10: =I10*(1+Assumptions!G14) | K10: Product information, branding, and regulatory labeling
A11: Packaging Materials | B11: Shipping Materials | C11: Cost per unit × units produced | D11: 0.15 | E11: =Assumptions!C15*100000 | F11: =D11*E11 | G11: =F11*(1+Assumptions!D14) | H11: =G11*(1+Assumptions!E14) | I11: =H11*(1+Assumptions!F14) | J11: =I11*(1+Assumptions!G14) | K11: Materials for safe product shipping
A12: Direct Labor | B12: Production Line Workers | C12: Hourly rate × hours per unit × units produced | D12: 0.80 | E12: =Assumptions!C15*100000 | F12: =D12*E12 | G12: =F12*(1+Assumptions!D14) | H12: =G12*(1+Assumptions!E14) | I12: =H12*(1+Assumptions!F14) | J12: =I12*(1+Assumptions!G14) | K12: Workers directly involved in product manufacturing
A13: Direct Labor | B13: Quality Inspectors | C13: Hourly rate × hours per unit × units produced | D13: 0.30 | E13: =Assumptions!C15*100000 | F13: =D13*E13 | G13: =F13*(1+Assumptions!D14) | H13: =G13*(1+Assumptions!E14) | I13: =H13*(1+Assumptions!F14) | J13: =I13*(1+Assumptions!G14) | K13: Staff dedicated to quality inspection during production
A14: Direct Labor | B14: Material Handlers | C14: Hourly rate × hours per unit × units produced | D14: 0.20 | E14: =Assumptions!C15*100000 | F14: =D14*E14 | G14: =F14*(1+Assumptions!D14) | H14: =G14*(1+Assumptions!E14) | I14: =H14*(1+Assumptions!F14) | J14: =I14*(1+Assumptions!G14) | K14: Workers handling materials and inventory on production floor
A15: Manufacturing Overhead | B15: Production Supervision | C15: Salary × headcount | D15: 0.40 | E15: 12 | F15: =D15*E15 | G15: =F15*(1+Assumptions!D14) | H15: =G15*(1+Assumptions!E14) | I15: =H15*(1+Assumptions!F14) | J15: =I15*(1+Assumptions!G14) | K15: Production managers and supervisors
A16: Manufacturing Overhead | B16: Manufacturing Utilities | C16: Usage rates × utility prices | D16: 0.25 | E16: 12 | F16: =D16*E16 | G16: =F16*(1+Assumptions!D14) | H16: =G16*(1+Assumptions!E14) | I16: =H16*(1+Assumptions!F14) | J16: =I16*(1+Assumptions!G14) | K16: Electricity, water, and other utilities for production
A17: Manufacturing Overhead | B17: Equipment Depreciation | C17: Equipment value ÷ useful life | D17: 0.35 | E17: 1 | F17: =D17*E17 | G17: =F17*(1+Assumptions!D14) | H17: =G17*(1+Assumptions!E14) | I17: =H17*(1+Assumptions!F14) | J17: =I17*(1+Assumptions!G14) | K17: Allocation of equipment cost over its useful life
A18: Manufacturing Overhead | B18: Production Supplies | C18: Cost per production run × number of runs | D18: 0.15 | E18: 52 | F18: =D18*E18 | G18: =F18*(1+Assumptions!D14) | H18: =G18*(1+Assumptions!E14) | I18: =H18*(1+Assumptions!F14) | J18: =I18*(1+Assumptions!G14) | K18: Gloves, cleaning supplies, and other production consumables
A19: Contract Manufacturing | B19: Contract Manufacturing Fees | C19: Fee per unit × units outsourced | D19: 1.50 | E19: =Assumptions!C15*100000*0.2 | F19: =D19*E19 | G19: =F19*(1+Assumptions!D14) | H19: =G19*(1+Assumptions!E14) | I19: =H19*(1+Assumptions!F14) | J19: =I19*(1+Assumptions!G14) | K19: Fees paid to third-party manufacturers for production
A20: Contract Manufacturing | B20: Formulation Services | C20: Fixed fee per formulation × number of formulations | D20: 0.30 | E20: 10 | F20: =D20*E20 | G20: =F20*(1+Assumptions!D14) | H20: =G20*(1+Assumptions!E14) | I20: =H20*(1+Assumptions!F14) | J20: =I20*(1+Assumptions!G14) | K20: Costs for external formulation development services
A21: Quality Control | B21: Raw Material Testing | C21: Cost per test × number of tests | D21: 0.20 | E21: =Assumptions!C15*100000*0.1 | F21: =D21*E21 | G21: =F21*(1+Assumptions!D14) | H21: =G21*(1+Assumptions!E14) | I21: =H21*(1+Assumptions!F14) | J21: =I21*(1+Assumptions!G14) | K21: Laboratory testing of incoming raw materials
A22: Quality Control | B22: In-Process Testing | C22: Cost per test × number of tests | D22: 0.15 | E22: =Assumptions!C15*100000*0.05 | F22: =D22*E22 | G22: =F22*(1+Assumptions!D14) | H22: =G22*(1+Assumptions!E14) | I22: =H22*(1+Assumptions!F14) | J22: =I22*(1+Assumptions!G14) | K22: Testing during the production process
A23: Quality Control | B23: Finished Product Testing | C23: Cost per test × number of tests | D23: 0.25 | E23: =Assumptions!C15*100000*0.1 | F23: =D23*E23 | G23: =F23*(1+Assumptions!D14) | H23: =G23*(1+Assumptions!E14) | I23: =H23*(1+Assumptions!F14) | J23: =I23*(1+Assumptions!G14) | K23: Final product quality verification testing
A24: Freight & Logistics (Inbound) | B24: Raw Material Freight | C24: Freight cost per shipment × number of shipments | D24: 0.18 | E24: 52 | F24: =D24*E24 | G24: =F24*(1+Assumptions!D14) | H24: =G24*(1+Assumptions!E14) | I24: =H24*(1+Assumptions!F14) | J24: =I24*(1+Assumptions!G14) | K24: Transportation costs for raw material delivery
A25: Freight & Logistics (Inbound) | B25: Import Duties & Customs | C25: Percentage of imported material value | D25: 0.12 | E25: =Assumptions!C15*100000*0.3 | F25: =D25*E25 | G25: =F25*(1+Assumptions!D14) | H25: =G25*(1+Assumptions!E14) | I25: =H25*(1+Assumptions!F14) | J25: =I25*(1+Assumptions!G14) | K25: Taxes and fees for imported materials
A26: Freight & Logistics (Inbound) | B26: Inbound Logistics Management | C26: Fixed monthly cost | D26: 0.10 | E26: 12 | F26: =D26*E26 | G26: =F26*(1+Assumptions!D14) | H26: =G26*(1+Assumptions!E14) | I26: =H26*(1+Assumptions!F14) | J26: =I26*(1+Assumptions!G14) | K26: Costs for managing inbound logistics operations
A28: Total COGS | F28: =SUM(F3:F27) | G28: =SUM(G3:G27) | H28: =SUM(H3:H27) | I28: =SUM(I3:I27) | J28: =SUM(J3:J27)
A30: COGS per Unit | F30: =F28/100000 | G30: =G28/100000 | H30: =H28/100000 | I30: =I28/100000 | J30: =J28/100000
A32: COGS as % of Revenue | F32: =F28/100000 | G32: =G28/100000 | H32: =H28/100000 | I32: =I28/100000 | J32: =J28/100000

Sheet SG&A
A1: Selling, General & Administrative (SG&A) Expenses
A2: Cost Category | B2: Cost Item | C2: Cost Driver | D2: Annual Cost Base | E2: Year 1 Total | F2: Year 2 Total | G2: Year 3 Total | H2: Year 4 Total | I2: Year 5 Total | J2: Notes
A3: Sales Expenses | B3: Sales Team Salaries | C3: Headcount × average salary | D3: =Assumptions!C31*8 | E3: =D3 | F3: =E3*(1+Assumptions!D31) | G3: =F3*(1+Assumptions!E31) | H3: =G3*(1+Assumptions!F31) | I3: =H3*(1+Assumptions!G31) | J3: Base salaries for sales team members
A4: Sales Expenses | B4: Sales Commissions | C4: Percentage of revenue | D4: =Assumptions!C32 | E4: =D4 | F4: =E4*(1+Assumptions!D32) | G4: =F4*(1+Assumptions!E32) | H4: =G4*(1+Assumptions!F32) | I4: =H4*(1+Assumptions!G32) | J4: Variable compensation based on sales performance
A5: Sales Expenses | B5: Travel & Entertainment | C5: Per sales employee × travel frequency | D5: =15000 | E5: =D5 | F5: =E5*(1+Assumptions!D4) | G5: =F5*(1+Assumptions!E4) | H5: =G5*(1+Assumptions!F4) | I5: =H5*(1+Assumptions!G4) | J5: Customer meetings, sales trips, and entertainment expenses
A6: Sales Expenses | B6: Trade Shows & Events | C6: Fixed cost per event × number of events | D6: =25000*4 | E6: =D6 | F6: =E6*(1+Assumptions!D4) | G6: =F6*(1+Assumptions!E4) | H6: =G6*(1+Assumptions!F4) | I6: =H6*(1+Assumptions!G4) | J6: Industry exhibitions, conferences, and sales events
A7: Sales Expenses | B7: Customer Relationship Management | C7: Per user license fee × number of users | D7: =Assumptions!C36*25 | E7: =D7 | F7: =E7*(1+Assumptions!D4) | G7: =F7*(1+Assumptions!E4) | H7: =G7*(1+Assumptions!F4) | I7: =H7*(1+Assumptions!G4) | J7: Software for managing customer relationships and sales pipeline
A8: Marketing Expenses | B8: Digital Marketing | C8: Percentage of revenue | D8: =Assumptions!C33 | E8: =D8 | F8: =E8*(1+Assumptions!D33) | G8: =F8*(1+Assumptions!E33) | H8: =G8*(1+Assumptions!F33) | I8: =H8*(1+Assumptions!G33) | J8: Online advertising, SEO, email marketing, and other digital channels
A9: Marketing Expenses | B9: Traditional Advertising | C9: Percentage of revenue | D9: =0.03*1000000 | E9: =D9 | F9: =E9*(1+Assumptions!D33) | G9: =F9*(1+Assumptions!E33) | H9: =G9*(1+Assumptions!F33) | I9: =H9*(1+Assumptions!G33) | J9: Print, TV, radio, and other traditional media advertising
A10: Marketing Expenses | B10: Social Media Marketing | C10: Percentage of revenue | D10: =0.02*1000000 | E10: =D10 | F10: =E10*(1+Assumptions!D33) | G10: =F10*(1+Assumptions!E33) | H10: =G10*(1+Assumptions!F33) | I10: =H10*(1+Assumptions!G33) | J10: Content creation, community management, and paid social campaigns
A11: Marketing Expenses | B11: Influencer Partnerships | C11: Fixed fee per partnership × number of partnerships | D11: =20000*12 | E11: =D11 | F11: =E11*(1+Assumptions!D4) | G11: =F11*(1+Assumptions!E4) | H11: =G11*(1+Assumptions!F4) | I11: =H11*(1+Assumptions!G4) | J11: Partnerships with industry influencers and content creators
A12: Marketing Expenses | B12: Public Relations | C12: Monthly retainer × 12 | D12: =10000*12 | E12: =D12 | F12: =E12*(1+Assumptions!D4) | G12: =F12*(1+Assumptions!E4) | H12: =G12*(1+Assumptions!F4) | I12: =H12*(1+Assumptions!G4) | J12: Media relations, press releases, and publicity management
A13: Marketing Expenses | B13: Marketing Materials | C13: Fixed cost per campaign × number of campaigns | D13: =15000*4 | E13: =D13 | F13: =E13*(1+Assumptions!D4) | G13: =F13*(1+Assumptions!E4) | H13: =G13*(1+Assumptions!F4) | I13: =H13*(1+Assumptions!G4) | J13: Brochures, catalogs, samples, and other physical marketing materials
A14: General Administrative | B14: Executive Salaries | C14: Headcount × average salary | D14: =250000*4 | E14: =D14 | F14: =E14*(1+Assumptions!D4) | G14: =F14*(1+Assumptions!E4) | H14: =G14*(1+Assumptions!F4) | I14: =H14*(1+Assumptions!G4) | J14: C-suite and senior management compensation
A15: General Administrative | B15: Administrative Staff | C15: Headcount × average salary | D15: =Assumptions!C34*10 | E15: =D15 | F15: =E15*(1+Assumptions!D34) | G15: =F15*(1+Assumptions!E34) | H15: =G15*(1+Assumptions!F34) | I15: =H15*(1+Assumptions!G34) | J15: Support staff, office management, and administrative personnel
A16: General Administrative | B16: HR Department | C16: Headcount × average salary | D16: =80000*3 | E16: =D16 | F16: =E16*(1+Assumptions!D4) | G16: =F16*(1+Assumptions!E4) | H16: =G16*(1+Assumptions!F4) | I16: =H16*(1+Assumptions!G4) | J16: Recruitment, benefits administration, and employee relations
A17: General Administrative | B17: Finance Department | C17: Headcount × average salary | D17: =90000*4 | E17: =D17 | F17: =E17*(1+Assumptions!D4) | G17: =F17*(1+Assumptions!E4) | H17: =G17*(1+Assumptions!F4) | I17: =H17*(1+Assumptions!G4) | J17: Accounting, financial planning, and treasury operations
A18: General Administrative | B18: Corporate Insurance | C18: Percentage of revenue | D18: =0.005*1000000 | E18: =D18 | F18: =E18*(1+Assumptions!D4) | G18: =F18*(1+Assumptions!E4) | H18: =G18*(1+Assumptions!F4) | I18: =H18*(1+Assumptions!G4) | J18: General liability, D&O, and other corporate insurance policies
A19: Professional Services | B19: Legal Services | C19: Monthly retainer + hourly fees | D19: =Assumptions!C37 | E19: =D19 | F19: =E19*(1+Assumptions!D37) | G19: =F19*(1+Assumptions!E37) | H19: =G19*(1+Assumptions!F37) | I19: =H19*(1+Assumptions!G37) | J19: Outside counsel, legal advice, and contract review
A20: Professional Services | B20: Accounting & Audit | C20: Annual audit fee + monthly accounting | D20: =Assumptions!C37*0.8 | E20: =D20 | F20: =E20*(1+Assumptions!D37) | G20: =F20*(1+Assumptions!E37) | H20: =G20*(1+Assumptions!F37) | I20: =H20*(1+Assumptions!G37) | J20: External accounting services and annual financial audits
A21: Professional Services | B21: Consulting Services | C21: Project-based fees | D21: =50000*2 | E21: =D21 | F21: =E21*(1+Assumptions!D4) | G21: =F21*(1+Assumptions!E4) | H21: =G21*(1+Assumptions!F4) | I21: =H21*(1+Assumptions!G4) | J21: Business strategy, operations, and specialized consulting
A22: Professional Services | B22: Regulatory Compliance | C22: Fixed annual cost | D22: =75000 | E22: =D22 | F22: =E22*(1+Assumptions!D4) | G22: =F22*(1+Assumptions!E4) | H22: =G22*(1+Assumptions!F4) | I22: =H22*(1+Assumptions!G4) | J22: Costs for ensuring compliance with industry regulations
A23: IT & Technology | B23: IT Staff | C23: Headcount × average salary | D23: =120000*3 | E23: =D23 | F23: =E23*(1+Assumptions!D4) | G23: =F23*(1+Assumptions!E4) | H23: =G23*(1+Assumptions!F4) | I23: =H23*(1+Assumptions!G4) | J23: IT department personnel and support staff
A24: IT & Technology | B24: Software Licenses | C24: Per user license fee × number of users | D24: =Assumptions!C36*50 | E24: =D24 | F24: =E24*(1+Assumptions!D36) | G24: =F24*(1+Assumptions!E36) | H24: =G24*(1+Assumptions!F36) | I24: =H24*(1+Assumptions!G36) | J24: Software subscriptions and enterprise applications
A25: IT & Technology | B25: Hardware & Equipment | C25: Depreciation + new purchases | D25: =100000 | E25: =D25 | F25: =E25*(1+Assumptions!D4) | G25: =F25*(1+Assumptions!E4) | H25: =G25*(1+Assumptions!F4) | I25: =H25*(1+Assumptions!G4) | J25: Computers, servers, networking equipment, and peripherals
A26: IT & Technology | B26: IT Support & Maintenance | C26: Monthly service fee × 12 | D26: =8000*12 | E26: =D26 | F26: =E26*(1+Assumptions!D4) | G26: =F26*(1+Assumptions!E4) | H26: =G26*(1+Assumptions!F4) | I26: =H26*(1+Assumptions!G4) | J26: Ongoing IT maintenance, security, and support services
A27: Facilities & Office | B27: Office Rent | C27: Square footage × rate with annual increase | D27: =Assumptions!C35*5000 | E27: =D27 | F27: =E27*(1+Assumptions!D35) | G27: =F27*(1+Assumptions!E35) | H27: =G27*(1+Assumptions!F35) | I27: =H27*(1+Assumptions!G35) | J27: Lease or rent payments for office space
A28: Facilities & Office | B28: Office Utilities | C28: Usage rates × utility prices | D28: =4000*12 | E28: =D28 | F28: =E28*(1+Assumptions!D4) | G28: =F28*(1+Assumptions!E4) | H28: =G28*(1+Assumptions!F4) | I28: =H28*(1+Assumptions!G4) | J28: Electricity, water, heating, and other office utilities
A29: Facilities & Office | B29: Office Supplies | C29: Per employee × headcount | D29: =500*50 | E29: =D29 | F29: =E29*(1+Assumptions!D4) | G29: =F29*(1+Assumptions!E4) | H29: =G29*(1+Assumptions!F4) | I29: =H29*(1+Assumptions!G4) | J29: Office consumables, stationery, and supplies
A30: Facilities & Office | B30: Office Maintenance | C30: Percentage of facility value | D30: =0.02*1000000 | E30: =D30 | F30: =E30*(1+Assumptions!D4) | G30: =F30*(1+Assumptions!E4) | H30: =G30*(1+Assumptions!F4) | I30: =H30*(1+Assumptions!G4) | J30: Cleaning, repairs, and general office maintenance
A31: Other SG&A | B31: Training & Development | C31: Training budget per employee × headcount | D31: =Assumptions!C47*50 | E31: =D31 | F31: =E31*(1+Assumptions!D4) | G31: =F31*(1+Assumptions!E4) | H31: =G31*(1+Assumptions!F4) | I31: =H31*(1+Assumptions!G4) | J31: Employee development programs and educational resources
A32: Other SG&A | B32: Travel (Non-Sales) | C32: Per employee × travel frequency | D32: =3000*20 | E32: =D32 | F32: =E32*(1+Assumptions!D4) | G32: =F32*(1+Assumptions!E4) | H32: =G32*(1+Assumptions!F4) | I32: =H32*(1+Assumptions!G4) | J32: Non-sales related business travel expenses
A33: Other SG&A | B33: Miscellaneous SG&A | C33: Percentage of total SG&A | D33: =0.01*SUM(D3:D29) | E33: =D33 | F33: =E33*(1+Assumptions!D4) | G33: =F33*(1+Assumptions!E4) | H33: =G33*(1+Assumptions!F4) | I33: =H33*(1+Assumptions!G4) | J33: Miscellaneous selling, general, and administrative expenses
A35: Total Sales Expenses | E35: =SUM(E3:E7) | F35: =SUM(F3:F7) | G35: =SUM(G3:G7) | H35: =SUM(H3:H7) | I35: =SUM(I3:I7)
A36: Total Marketing Expenses | E36: =SUM(E8:E13) | F36: =SUM(F8:F13) | G36: =SUM(G8:G13) | H36: =SUM(H8:H13) | I36: =SUM(I8:I13)
A37: Total General Administrative | E37: =SUM(E14:E18) | F37: =SUM(F14:F18) | G37: =SUM(G14:G18) | H37: =SUM(H14:H18) | I37: =SUM(I14:I18)
A38: Total Professional Services | E38: =SUM(E19:E22) | F38: =SUM(F19:F22) | G38: =SUM(G19:G22) | H38: =SUM(H19:H22) | I38: =SUM(I19:I22)
A39: Total IT & Technology | E39: =SUM(E23:E26) | F39: =SUM(F23:F26) | G39: =SUM(G23:G26) | H39: =SUM(H23:H26) | I39: =SUM(I23:I26)
A40: Total Facilities & Office | E40: =SUM(E27:E30) | F40: =SUM(F27:F30) | G40: =SUM(G27:G30) | H40: =SUM(H27:H30) | I40: =SUM(I27:I30)
A41: Total Other SG&A | E41: =SUM(E31:E33) | F41: =SUM(F31:F33) | G41: =SUM(G31:G33) | H41: =SUM(H31:H33) | I41: =SUM(I31:I33)
...

Sheet Revenue
A1: Revenue and Profitability
A2: Revenue Category | B2: Revenue Stream | C2: Revenue Driver | D2: Year 1 Units | E2: Year 1 Price | F2: Year 1 Revenue | G2: Year 2 Revenue | H2: Year 3 Revenue | I2: Year 4 Revenue | J2: Year 5 Revenue | K2: Notes
A3: Product Categories | B3: Facial Skincare | C3: Units sold × average price | D3: 500000 | E3: 25.00 | F3: =D3*E3 | G3: =F3*(1+Assumptions!D8)*(1+Assumptions!D12) | H3: =G3*(1+Assumptions!E8)*(1+Assumptions!E12) | I3: =H3*(1+Assumptions!F8)*(1+Assumptions!F12) | J3: =I3*(1+Assumptions!G8)*(1+Assumptions!G12) | K3: Cleansers, moisturizers, serums, masks for facial care
A4: Product Categories | B4: Body Care | C4: Units sold × average price | D4: 300000 | E4: 22.00 | F4: =D4*E4 | G4: =F4*(1+Assumptions!D9)*(1+Assumptions!D12) | H4: =G4*(1+Assumptions!E9)*(1+Assumptions!E12) | I4: =H4*(1+Assumptions!F9)*(1+Assumptions!F12) | J4: =I4*(1+Assumptions!G9)*(1+Assumptions!G12) | K4: Lotions, scrubs, oils for body care
A5: Product Categories | B5: Specialty Products | C5: Units sold × average price | D5: 100000 | E5: 35.00 | F5: =D5*E5 | G5: =F5*(1+Assumptions!D10)*(1+Assumptions!D12) | H5: =G5*(1+Assumptions!E10)*(1+Assumptions!E12) | I5: =H5*(1+Assumptions!F10)*(1+Assumptions!F12) | J5: =I5*(1+Assumptions!G10)*(1+Assumptions!G12) | K5: Anti-aging, acne treatment, sun protection
A6: Distribution Channels | B6: Direct-to-Consumer (DTC) | C6: Website traffic × conversion rate × average order value | D6: 400000 | E6: 28.00 | F6: =D6*E6 | G6: =F6*(1+Assumptions!D10)*(1+Assumptions!D12) | H6: =G6*(1+Assumptions!E10)*(1+Assumptions!E12) | I6: =H6*(1+Assumptions!F10)*(1+Assumptions!F12) | J6: =I6*(1+Assumptions!G10)*(1+Assumptions!G12) | K6: Sales through company website and branded apps
A7: Distribution Channels | B7: Retail | C7: Store count × average sales per store | D7: 350000 | E7: 24.00 | F7: =D7*E7 | G7: =F7*(1+Assumptions!D11)*(1+Assumptions!D12) | H7: =G7*(1+Assumptions!E11)*(1+Assumptions!E12) | I7: =H7*(1+Assumptions!F11)*(1+Assumptions!F12) | J7: =I7*(1+Assumptions!G11)*(1+Assumptions!G12) | K7: Sales through retail partners and own stores
A8: Distribution Channels | B8: Wholesale/B2B | C8: Number of wholesale accounts × average order size × order frequency | D8: 150000 | E8: 20.00 | F8: =D8*E8 | G8: =F8*(1+Assumptions!D7)*(1+Assumptions!D12) | H8: =G8*(1+Assumptions!E7)*(1+Assumptions!E12) | I8: =H8*(1+Assumptions!F7)*(1+Assumptions!F12) | J8: =I8*(1+Assumptions!G7)*(1+Assumptions!G12) | K8: Sales to salons, spas, and other businesses
A9: Geographic Markets | B9: Domestic | C9: Market size × market share | D9: 600000 | E9: 26.00 | F9: =D9*E9 | G9: =F9*(1+Assumptions!D7)*(1+Assumptions!D12) | H9: =G9*(1+Assumptions!E7)*(1+Assumptions!E12) | I9: =H9*(1+Assumptions!F7)*(1+Assumptions!F12) | J9: =I9*(1+Assumptions!G7)*(1+Assumptions!G12) | K9: Sales within primary country of operation
A10: Geographic Markets | B10: International - Developed | C10: Market size × market share | D10: 200000 | E10: 30.00 | F10: =D10*E10 | G10: =F10*(1+Assumptions!D7)*(1+Assumptions!D12) | H10: =G10*(1+Assumptions!E7)*(1+Assumptions!E12) | I10: =H10*(1+Assumptions!F7)*(1+Assumptions!F12) | J10: =I10*(1+Assumptions!G7)*(1+Assumptions!G12) | K10: Sales in established international markets
A11: Geographic Markets | B11: International - Emerging | C11: Market size × market share | D11: 100000 | E11: 22.00 | F11: =D11*E11 | G11: =F11*(1+Assumptions!D7)*(1+Assumptions!D12) | H11: =G11*(1+Assumptions!E7)*(1+Assumptions!E12) | I11: =H11*(1+Assumptions!F7)*(1+Assumptions!F12) | J11: =I11*(1+Assumptions!G7)*(1+Assumptions!G12) | K11: Sales in developing international markets
A13: Total Revenue | F13: =SUM(F3:F12) | G13: =SUM(G3:G12) | H13: =SUM(H3:H12) | I13: =SUM(I3:I12) | J13: =SUM(J3:J12)
A16: Profitability Analysis
A17: Metric | F17: Year 1 | G17: Year 2 | H17: Year 3 | I17: Year 4 | J17: Year 5
A18: Revenue | F18: =F13 | G18: =G13 | H18: =H13 | I18: =I13 | J18: =J13
A19: Cost of Goods Sold (COGS) | F19: =COGS!F30 | G19: =COGS!G30 | H19: =COGS!H30 | I19: =COGS!I30 | J19: =COGS!J30
A20: Gross Profit | F20: =INDEX(F:J,20-2,MATCH(F$17,F$17:J$17,0))-INDEX(F:J,20-1,MATCH(F$17,F$17:J$17,0)) | G20: =INDEX(F:J,20-2,MATCH(G$17,F$17:J$17,0))-INDEX(F:J,20-1,MATCH(G$17,F$17:J$17,0)) | H20: =INDEX(F:J,20-2,MATCH(H$17,F$17:J$17,0))-INDEX(F:J,20-1,MATCH(H$17,F$17:J$17,0)) | I20: =INDEX(F:J,20-2,MATCH(I$17,F$17:J$17,0))-INDEX(F:J,20-1,MATCH(I$17,F$17:J$17,0)) | J20: =INDEX(F:J,20-2,MATCH(J$17,F$17:J$17,0))-INDEX(F:J,20-1,MATCH(J$17,F$17:J$17,0))
A21: Gross Margin % | F21: =INDEX(F:J,21-1,MATCH(F$17,F$17:J$17,0))/INDEX(F:J,21-3,MATCH(F$17,F$17:J$17,0)) | G21: =INDEX(F:J,21-1,MATCH(G$17,F$17:J$17,0))/INDEX(F:J,21-3,MATCH(G$17,F$17:J$17,0)) | H21: =INDEX(F:J,21-1,MATCH(H$17,F$17:J$17,0))/INDEX(F:J,21-3,MATCH(H$17,F$17:J$17,0)) | I21: =INDEX(F:J,21-1,MATCH(I$17,F$17:J$17,0))/INDEX(F:J,21-3,MATCH(I$17,F$17:J$17,0)) | J21: =INDEX(F:J,21-1,MATCH(J$17,F$17:J$17,0))/INDEX(F:J,21-3,MATCH(J$17,F$17:J$17,0))
A22: Operational Costs | F22: ='Operational Costs'!F30 | G22: ='Operational Costs'!G30 | H22: ='Operational Costs'!H30 | I22: ='Operational Costs'!I30 | J22: ='Operational Costs'!J30
A23: SG&A Expenses | F23: ='SG&A'!F40 | G23: ='SG&A'!G40 | H23: ='SG&A'!H40 | I23: ='SG&A'!I40 | J23: ='SG&A'!J40
A24: EBITDA | F24: =INDEX(F:J,24-4,MATCH(F$17,F$17:J$17,0))-INDEX(F:J,24-2,MATCH(F$17,F$17:J$17,0))-INDEX(F:J,24-1,MATCH(F$17,F$17:J$17,0)) | G24: =INDEX(F:J,24-4,MATCH(G$17,F$17:J$17,0))-INDEX(F:J,24-2,MATCH(G$17,F$17:J$17,0))-INDEX(F:J,24-1,MATCH(G$17,F$17:J$17,0)) | H24: =INDEX(F:J,24-4,MATCH(H$17,F$17:J$17,0))-INDEX(F:J,24-2,MATCH(H$17,F$17:J$17,0))-INDEX(F:J,24-1,MATCH(H$17,F$17:J$17,0)) | I24: =INDEX(F:J,24-4,MATCH(I$17,F$17:J$17,0))-INDEX(F:J,24-2,MATCH(I$17,F$17:J$17,0))-INDEX(F:J,24-1,MATCH(I$17,F$17:J$17,0)) | J24: =INDEX(F:J,24-4,MATCH(J$17,F$17:J$17,0))-INDEX(F:J,24-2,MATCH(J$17,F$17:J$17,0))-INDEX(F:J,24-1,MATCH(J$17,F$17:J$17,0))
A25: EBITDA Margin % | F25: =INDEX(F:J,25-1,MATCH(F$17,F$17:J$17,0))/INDEX(F:J,25-7,MATCH(F$17,F$17:J$17,0)) | G25: =INDEX(F:J,25-1,MATCH(G$17,F$17:J$17,0))/INDEX(F:J,25-7,MATCH(G$17,F$17:J$17,0)) | H25: =INDEX(F:J,25-1,MATCH(H$17,F$17:J$17,0))/INDEX(F:J,25-7,MATCH(H$17,F$17:J$17,0)) | I25: =INDEX(F:J,25-1,MATCH(I$17,F$17:J$17,0))/INDEX(F:J,25-7,MATCH(I$17,F$17:J$17,0)) | J25: =INDEX(F:J,25-1,MATCH(J$17,F$17:J$17,0))/INDEX(F:J,25-7,MATCH(J$17,F$17:J$17,0))
A26: Depreciation & Amortization | F26: =100000 | G26: =100000 | H26: =100000 | I26: =100000 | J26: =100000
A27: EBIT | F27: =INDEX(F:J,27-3,MATCH(F$17,F$17:J$17,0))-INDEX(F:J,27-1,MATCH(F$17,F$17:J$17,0)) | G27: =INDEX(F:J,27-3,MATCH(G$17,F$17:J$17,0))-INDEX(F:J,27-1,MATCH(G$17,F$17:J$17,0)) | H27: =INDEX(F:J,27-3,MATCH(H$17,F$17:J$17,0))-INDEX(F:J,27-1,MATCH(H$17,F$17:J$17,0)) | I27: =INDEX(F:J,27-3,MATCH(I$17,F$17:J$17,0))-INDEX(F:J,27-1,MATCH(I$17,F$17:J$17,0)) | J27: =INDEX(F:J,27-3,MATCH(J$17,F$17:J$17,0))-INDEX(F:J,27-1,MATCH(J$17,F$17:J$17,0))
A28: Interest Expense | F28: =Assumptions!F61*1000000 | G28: =Assumptions!G61*1000000 | H28: =Assumptions!H61*1000000 | I28: =Assumptions!I61*1000000 | J28: =Assumptions!J61*1000000
A29: EBT | F29: =INDEX(F:J,29-2,MATCH(F$17,F$17:J$17,0))-INDEX(F:J,29-1,MATCH(F$17,F$17:J$17,0)) | G29: =INDEX(F:J,29-2,MATCH(G$17,F$17:J$17,0))-INDEX(F:J,29-1,MATCH(G$17,F$17:J$17,0)) | H29: =INDEX(F:J,29-2,MATCH(H$17,F$17:J$17,0))-INDEX(F:J,29-1,MATCH(H$17,F$17:J$17,0)) | I29: =INDEX(F:J,29-2,MATCH(I$17,F$17:J$17,0))-INDEX(F:J,29-1,MATCH(I$17,F$17:J$17,0)) | J29: =INDEX(F:J,29-2,MATCH(J$17,F$17:J$17,0))-INDEX(F:J,29-1,MATCH(J$17,F$17:J$17,0))
A30: Income Tax | F30: =INDEX(F:J,30-1,MATCH(F$17,F$17:J$17,0))*Assumptions!F6 | G30: =INDEX(F:J,30-1,MATCH(G$17,F$17:J$17,0))*Assumptions!G6 | H30: =INDEX(F:J,30-1,MATCH(H$17,F$17:J$17,0))*Assumptions!H6 | I30: =INDEX(F:J,30-1,MATCH(I$17,F$17:J$17,0))*Assumptions!I6 | J30: =INDEX(F:J,30-1,MATCH(J$17,F$17:J$17,0))*Assumptions!J6
A31: Net Income | F31: =INDEX(F:J,31-2,MATCH(F$17,F$17:J$17,0))-INDEX(F:J,31-1,MATCH(F$17,F$17:J$17,0)) | G31: =INDEX(F:J,31-2,MATCH(G$17,F$17:J$17,0))-INDEX(F:J,31-1,MATCH(G$17,F$17:J$17,0)) | H31: =INDEX(F:J,31-2,MATCH(H$17,F$17:J$17,0))-INDEX(F:J,31-1,MATCH(H$17,F$17:J$17,0)) | I31: =INDEX(F:J,31-2,MATCH(I$17,F$17:J$17,0))-INDEX(F:J,31-1,MATCH(I$17,F$17:J$17,0)) | J31: =INDEX(F:J,31-2,MATCH(J$17,F$17:J$17,0))-INDEX(F:J,31-1,MATCH(J$17,F$17:J$17,0))
A32: Net Profit Margin % | F32: =INDEX(F:J,32-1,MATCH(F$17,F$17:J$17,0))/INDEX(F:J,32-14,MATCH(F$17,F$17:J$17,0)) | G32: =INDEX(F:J,32-1,MATCH(G$17,F$17:J$17,0))/INDEX(F:J,32-14,MATCH(G$17,F$17:J$17,0)) | H32: =INDEX(F:J,32-1,MATCH(H$17,F$17:J$17,0))/INDEX(F:J,32-14,MATCH(H$17,F$17:J$17,0)) | I32: =INDEX(F:J,32-1,MATCH(I$17,F$17:J$17,0))/INDEX(F:J,32-14,MATCH(I$17,F$17:J$17,0)) | J32: =INDEX(F:J,32-1,MATCH(J$17,F$17:J$17,0))/INDEX(F:J,32-14,MATCH(J$17,F$17:J$17,0))
A35: Scenario Analysis
A36: Scenario | B36: Revenue Growth | C36: COGS % | D36: SG&A % | E36: Year 1 Revenue | F36: Year 5 Revenue | G36: Year 1 Net Income | H36: Year 5 Net Income | I36: Year 1 Margin | J36: Year 5 Margin
A37: Base Case | B37: =Assumptions!C7 | C37: =COGS!F29/F24 | D37: ='SG&A'!F39/F24 | E37: =F13 | F37: =J13 | G37: =F31 | H37: =J31 | I37: =G37/E37 | J37: =H37/F37
A38: Optimistic | B38: =Assumptions!C7*1.2 | C38: =COGS!F29/F24*0.9 | D38: ='SG&A'!F39/F24*0.9 | E38: =F13*1.1 | F38: =J13*1.2 | G38: =F31*1.3 | H38: =J31*1.4 | I38: =G38/E38 | J38: =H38/F38
A39: Pessimistic | B39: =Assumptions!C7*0.8 | C39: =COGS!F29/F24*1.1 | D39: ='SG&A'!F39/F24*1.1 | E39: =F13*0.9 | F39: =J13*0.8 | G39: =F31*0.7 | H39: =J31*0.6 | I39: =G39/E39 | J39: =H39/F39
